Workbook

Sheet Campaign_data
A1: campaign_id | B1: total_impressions | C1: total_clicks | D1: total_spend | E1: reported_conversions | F1: reported_conversion_value | G1: ctr | H1: cpc | I1: cpm | J1: cost_per_reported_conversion | K1: HISTORIAL_ROAS
A2: 1 | B2: 53541140 | C2: 246737 | D2: 357489.87 | E2: 2500 | F2: 184552.75 | G2: 0.46 | H2: 1.45 | I2: 6.68 | J2: 143 | K2: =IFERROR(F2/D2,"") -> 0.5162461
A3: 2 | B3: 19182237 | C3: 98024 | D3: 140153.6 | E3: 949 | F3: 71035.21 | G3: 0.51 | H3: 1.43 | I3: 7.31 | J3: 147.69 | K3: =IFERROR(F3/D3,"") -> 0.50683828
A4: 3 | B4: 12687653 | C4: 57525 | D4: 0 | E4: 677 | F4: 49589.5 | G4: 0.45 | H4: 0 | I4: 0 | J4: 0 | K4: =IFERROR(F4/D4,"")
A5: 4 | B5: 4076899 | C5: 22129 | D5: 32056.78 | E5: 216 | F5: 15747.74 | G5: 0.54 | H5: 1.45 | I5: 7.86 | J5: 148.41 | K5: =IFERROR(F5/D5,"") -> 0.49124522 | O5: 2524740.6
A6: 5 | B6: 14880136 | C6: 82538 | D6: 0 | E6: 754 | F6: 56515.28 | G6: 0.55 | H6: 0 | I6: 0 | J6: 0 | K6: =IFERROR(F6/D6,"")
A7: 6 | B7: 25831878 | C7: 103365 | D7: 149718.02 | E7: 1036 | F7: 73123.85 | G7: 0.4 | H7: 1.45 | I7: 5.8 | J7: 144.52 | K7: =IFERROR(F7/D7,"") -> 0.48841048
A8: 7 | B8: 4873917 | C8: 24417 | D8: 0 | E8: 250 | F8: 17277.45 | G8: 0.5 | H8: 0 | I8: 0 | J8: 0 | K8: =IFERROR(F8/D8,"")
A9: 8 | B9: 7901173 | C9: 40374 | D9: 0 | E9: 445 | F9: 33664.1 | G9: 0.51 | H9: 0 | I9: 0 | J9: 0 | K9: =IFERROR(F9/D9,"")
A10: 9 | B10: 2833054 | C10: 14269 | D10: 0 | E10: 155 | F10: 11297.65 | G10: 0.5 | H10: 0 | I10: 0 | J10: 0 | K10: =IFERROR(F10/D10,"")
A11: 10 | B11: 3887947 | C11: 15413 | D11: 0 | E11: 169 | F11: 12381.38 | G11: 0.4 | H11: 0 | I11: 0 | J11: 0 | K11: =IFERROR(F11/D11,"")
A12: 11 | B12: 18806319 | C12: 52236 | D12: 0 | E12: 670 | F12: 55927.36 | G12: 0.28 | H12: 0 | I12: 0 | J12: 0 | K12: =IFERROR(F12/D12,"")
A13: 12 | B13: 12642791 | C13: 42922 | D13: 61832.66 | E13: 545 | F13: 37989.83 | G13: 0.34 | H13: 1.44 | I13: 4.89 | J13: 113.45 | K13: =IFERROR(F13/D13,"") -> 0.61439747
A14: 13 | B14: 18987363 | C14: 100409 | D14: 143808.6 | E14: 982 | F14: 74320.53 | G14: 0.53 | H14: 1.43 | I14: 7.57 | J14: 146.44 | K14: =IFERROR(F14/D14,"") -> 0.51680171
A15: 14 | B15: 4363366 | C15: 22152 | D15: 0 | E15: 247 | F15: 18505.25 | G15: 0.51 | H15: 0 | I15: 0 | J15: 0 | K15: =IFERROR(F15/D15,"")
A16: 15 | B16: 4545737 | C16: 27820 | D16: 0 | E16: 230 | F16: 16429.96 | G16: 0.61 | H16: 0 | I16: 0 | J16: 0 | K16: =IFERROR(F16/D16,"")
A17: 16 | B17: 2082146 | C17: 15199 | D17: 22442.93 | E17: 180 | F17: 11534.85 | G17: 0.73 | H17: 1.48 | I17: 10.78 | J17: 124.68 | K17: =IFERROR(F17/D17,"") -> 0.51396364
... A125: 124 | B125: 609424 | C125: 3389 | D125: 0 | E125: 36 | F125: 2258.35 | G125: 0.56 | H125: 0 | I125: 0 | J125: 0 | K125: =IFERROR(F125/D125,"")
A126: 125 | B126: 38168 | C126: 869 | D126: 0 | E126: 0 | F126: 0 | G126: 2.28 | H126: 0 | I126: 0 | K126: =IFERROR(F126/D126,"")
A127: 126 | B127: 1345059 | C127: 5692 | D127: 8004.37 | E127: 63 | F127: 4584 | G127: 0.42 | H127: 1.41 | I127: 5.95 | J127: 127.05 | K127: =IFERROR(F127/D127,"") -> 0.57268717
A128: 127 | B128: 2122270 | C128: 7889 | D128: 12081.17 | E128: 76 | F128: 4715.28 | G128: 0.37 | H128: 1.53 | I128: 5.69 | J128: 158.96 | K128: =IFERROR(F128/D128,"") -> 0.39029995
A129: 128 | B129: 312533 | C129: 2147 | D129: 2977.71 | E129: 28 | F129: 1895.71 | G129: 0.69 | H129: 1.39 | I129: 9.53 | J129: 106.35 | K129: =IFERROR(F129/D129,"") -> 0.63663352
A130: 129 | B130: 442451 | C130: 1815 | D130: 2759.02 | E130: 19 | F130: 1070.62 | G130: 0.41 | H130: 1.52 | I130: 6.24 | J130: 145.21 | K130: =IFERROR(F130/D130,"") -> 0.38804358
A131: 130 | B131: 3399208 | C131: 14403 | D131: 20498.26 | E131: 175 | F131: 12326.16 | G131: 0.42 | H131: 1.42 | I131: 6.03 | J131: 117.13 | K131: =IFERROR(F131/D131,"") -> 0.60132714
A132: 131 | B132: 400570 | C132: 2693 | D132: 3794.94 | E132: 27 | F132: 1690.08 | G132: 0.67 | H132: 1.41 | I132: 9.47 | J132: 140.55 | K132: =IFERROR(F132/D132,"") -> 0.44535091
A133: 132 | B133: 182363 | C133: 3096 | D133: 4473.52 | E133: 8 | F133: 817.36 | G133: 1.7 | H133: 1.44 | I133: 24.53 | J133: 559.19 | K133: =IFERROR(F133/D133,"") -> 0.18271071
A134: 133 | B134: 584 | C134: 14 | D134: 0 | E134: 0 | F134: 0 | G134: 2.4 | H134: 0 | I134: 0 | K134: =IFERROR(F134/D134,"")
A135: 134 | B135: 121630 | C135: 1588 | D135: 0 | E135: 7 | F135: 555.11 | G135: 1.31 | H135: 0 | I135: 0 | J135: 0 | K135: =IFERROR(F135/D135,"")
A136: 135 | B136: 133477 | C136: 1913 | D136: 0 | E136: 3 | F136: 256.46 | G136: 1.43 | H136: 0 | I136: 0 | J136: 0 | K136: =IFERROR(F136/D136,"")
A137: 136 | B137: 162162 | C137: 663 | D137: 964.81 | E137: 4 | F137: 128.99 | G137: 0.41 | H137: 1.46 | I137: 5.95 | J137: 241.2 | K137: =IFERROR(F137/D137,"") -> 0.13369472
A138: 137 | B138: 114924 | C138: 1488 | D138: 2223.02 | E138: 9 | F138: 1004.83 | G138: 1.29 | H138: 1.49 | I138: 19.34 | J138: 247 | K138: =IFERROR(F138/D138,"") -> 0.45201123
A139: 138 | B139: 320038 | C139: 2582 | D139: 3744.95 | E139: 21 | F139: 1328.98 | G139: 0.81 | H139: 1.45 | I139: 11.7 | J139: 178.33 | K139: =IFERROR(F139/D139,"") -> 0.35487256
A140: 139 | B140: 2486351 | C140: 15118 | D140: 21828.56 | E140: 139 | F140: 9791.78 | G140: 0.61 | H140: 1.44 | I140: 8.78 | J140: 157.04 | K140: =IFERROR(F140/D140,"") -> 0.44857654
A141: 140 | B141: 1641098 | C141: 7122 | D141: 10599.24 | E141: 73 | F141: 5410.47 | G141: 0.43 | H141: 1.49 | I141: 6.46 | J141: 145.2 | K141: =IFERROR(F141/D141,"") -> 0.5104583
A142: 141 | B142: 3614869 | C142: 8332 | D142: 11060.86 | E142: 150 | F142: 10049.43 | G142: 0.23 | H142: 1.33 | I142: 3.06 | J142: 73.74 | K142: =IFERROR(F142/D142,"") -> 0.90855774
A143: 142 | B143: 794847 | C143: 5618 | D143: 7877.1 | E143: 63 | F143: 4786.08 | G143: 0.71 | H143: 1.4 | I143: 9.91 | J143: 125.03 | K143: =IFERROR(F143/D143,"") -> 0.60759417
A144: 143 | B144: 552222 | C144: 1335 | D144: 2041.18 | E144: 19 | F144: 1419.36 | G144: 0.24 | H144: 1.53 | I144: 3.7 | J144: 107.43 | K144: =IFERROR(F144/D144,"") -> 0.69536249
A145: 144 | B145: 142452 | C145: 1352 | D145: 1952.79 | E145: 15 | F145: 1209.12 | G145: 0.95 | H145: 1.44 | I145: 13.71 | J145: 130.19 | K145: =IFERROR(F145/D145,"") -> 0.61917564
A146: 145 | B146: 1434326 | C146: 5381 | D146: 7351.19 | E146: 60 | F146: 4394.03 | G146: 0.38 | H146: 1.37 | I146: 5.13 | J146: 122.52 | K146: =IFERROR(F146/D146,"") -> 0.59773044
... A149: 148 | B149: 3013073 | C149: 16342 | D149: 23570.9 | E149: 138 | F149: 11554.66 | G149: 0.54 | H149: 1.44 | I149: 7.82 | J149: 170.8 | K149: =IFERROR(F149/D149,"") -> 0.49020869
...

Sheet Budget_Scenario
A1: campaign_id | B1: historical_spend | C1: historical_roas | D1: proposed_budget | E1: assumed_roas | F1: expected_conversion_value | G1: historic_conversion_value
A2: =Campaign_data!A2 -> 1 | B2: =Campaign_data!D2 -> 357489.87 | C2: =Campaign_data!K2 -> 0.5162461 | D2: =B2 -> 357489.87 | E2: =C2 -> 0.5162461 | F2: =IFERROR(D2*E2,"") -> 184552.75 | G2: =Campaign_data!F2 -> 184552.75 | I2: Total budget | J2: 3240599.2
A3: =Campaign_data!A3 -> 2 | B3: =Campaign_data!D3 -> 140153.6 | C3: =Campaign_data!K3 -> 0.50683828 | D3: =B3 -> 140153.6 | E3: =C3 -> 0.50683828 | F3: =IFERROR(D3*E3,"") -> 71035.21 | G3: =Campaign_data!F3 -> 71035.21 | I3: Allocated budget | J3: =SUM(D2:D601) -> 3240599.2
A4: =Campaign_data!A4 -> 3 | B4: =Campaign_data!D4 -> 0 | C4: =Campaign_data!K4 | D4: =B4 -> 0 | E4: =C4 | F4: =IFERROR(D4*E4,"") | G4: =Campaign_data!F4 -> 49589.5 | I4: Budget difference | J4: =J2-J3 -> 0
A5: =Campaign_data!A5 -> 4 | B5: =Campaign_data!D5 -> 32056.78 | C5: =Campaign_data!K5 -> 0.49124522 | D5: =B5 -> 32056.78 | E5: =C5 -> 0.49124522 | F5: =IFERROR(D5*E5,"") -> 15747.74 | G5: =Campaign_data!F5 -> 15747.74 | I5: Hiistorical Conversion Value | J5: =SUM(G2:G601) -> 2524740.6
A6: =Campaign_data!A6 -> 5 | B6: =Campaign_data!D6 -> 0 | C6: =Campaign_data!K6 | D6: =B6 -> 0 | E6: =C6 | F6: =IFERROR(D6*E6,"") | G6: =Campaign_data!F6 -> 56515.28 | I6: Historical Roas | J6: =J5/J2 -> 0.77909684
A7: =Campaign_data!A7 -> 6 | B7: =Campaign_data!D7 -> 149718.02 | C7: =Campaign_data!K7 -> 0.48841048 | D7: =B7 -> 149718.02 | E7: =C7 -> 0.48841048 | F7: =IFERROR(D7*E7,"") -> 73123.85 | G7: =Campaign_data!F7 -> 73123.85 | I7: Expected Conversion Value (including rows with total spend) | J7: =SUM(F2:F601) -> 1751987.8
A8: =Campaign_data!A8 -> 7 | B8: =Campaign_data!D8 -> 0 | C8: =Campaign_data!K8 | D8: =B8 -> 0 | E8: =C8 | F8: =IFERROR(D8*E8,"") | G8: =Campaign_data!F8 -> 17277.45 | I8: Expected/Scenario Roas | J8: =J7/J3 -> 0.54063699
A9: =Campaign_data!A9 -> 8 | B9: =Campaign_data!D9 -> 0 | C9: =Campaign_data!K9 | D9: =B9 -> 0 | E9: =C9 | F9: =IFERROR(D9*E9,"") | G9: =Campaign_data!F9 -> 33664.1
A10: =Campaign_data!A10 -> 9 | B10: =Campaign_data!D10 -> 0 | C10: =Campaign_data!K10 | D10: =B10 -> 0 | E10: =C10 | F10: =IFERROR(D10*E10,"") | G10: =Campaign_data!F10 -> 11297.65
A11: =Campaign_data!A11 -> 10 | B11: =Campaign_data!D11 -> 0 | C11: =Campaign_data!K11 | D11: =B11 -> 0 | E11: =C11 | F11: =IFERROR(D11*E11,"") | G11: =Campaign_data!F11 -> 12381.38
A12: =Campaign_data!A12 -> 11 | B12: =Campaign_data!D12 -> 0 | C12: =Campaign_data!K12 | D12: =B12 -> 0 | E12: =C12 | F12: =IFERROR(D12*E12,"") | G12: =Campaign_data!F12 -> 55927.36
A13: =Campaign_data!A13 -> 12 | B13: =Campaign_data!D13 -> 61832.66 | C13: =Campaign_data!K13 -> 0.61439747 | D13: =B13 -> 61832.66 | E13: =C13 -> 0.61439747 | F13: =IFERROR(D13*E13,"") -> 37989.83 | G13: =Campaign_data!F13 -> 37989.83
A14: =Campaign_data!A14 -> 13 | B14: =Campaign_data!D14 -> 143808.6 | C14: =Campaign_data!K14 -> 0.51680171 | D14: =B14 -> 143808.6 | E14: =C14 -> 0.51680171 | F14: =IFERROR(D14*E14,"") -> 74320.53 | G14: =Campaign_data!F14 -> 74320.53
A15: =Campaign_data!A15 -> 14 | B15: =Campaign_data!D15 -> 0 | C15: =Campaign_data!K15 | D15: =B15 -> 0 | E15: =C15 | F15: =IFERROR(D15*E15,"") | G15: =Campaign_data!F15 -> 18505.25
A16: =Campaign_data!A16 -> 15 | B16: =Campaign_data!D16 -> 0 | C16: =Campaign_data!K16 | D16: =B16 -> 0 | E16: =C16 | F16: =IFERROR(D16*E16,"") | G16: =Campaign_data!F16 -> 16429.96
A17: =Campaign_data!A17 -> 16 | B17: =Campaign_data!D17 -> 22442.93 | C17: =Campaign_data!K17 -> 0.51396364 | D17: =B17 -> 22442.93 | E17: =C17 -> 0.51396364 | F17: =IFERROR(D17*E17,"") -> 11534.85 | G17: =Campaign_data!F17 -> 11534.85
A18: =Campaign_data!A18 -> 17 | B18: =Campaign_data!D18 -> 52878.13 | C18: =Campaign_data!K18 -> 0.50443047 | D18: =B18 -> 52878.13 | E18: =C18 -> 0.50443047 | F18: =IFERROR(D18*E18,"") -> 26673.34 | G18: =Campaign_data!F18 -> 26673.34
A19: =Campaign_data!A19 -> 18 | B19: =Campaign_data!D19 -> 5230.07 | C19: =Campaign_data!K19 -> 0.47633588 | D19: =B19 -> 5230.07 | E19: =C19 -> 0.47633588 | F19: =IFERROR(D19*E19,"") -> 2491.27 | G19: =Campaign_data!F19 -> 2491.27
A20: =Campaign_data!A20 -> 19 | B20: =Campaign_data!D20 -> 123082.42 | C20: =Campaign_data!K20 -> 0.52823888 | D20: =B20 -> 123082.42 | E20: =C20 -> 0.52823888 | F20: =IFERROR(D20*E20,"") -> 65016.92 | G20: =Campaign_data!F20 -> 65016.92
... A41: =Campaign_data!A41 -> 40 | B41: =Campaign_data!D41 -> 0 | C41: =Campaign_data!K41 | D41: =B41 -> 0 | E41: =C41 | F41: =IFERROR(D41*E41,"") | G41: =Campaign_data!F41 -> 23807.98
A42: =Campaign_data!A42 -> 41 | B42: =Campaign_data!D42 -> 5308.87 | C42: =Campaign_data!K42 -> 0.39585637 | D42: =B42*95% -> 5043.4265 | E42: =C42 -> 0.39585637 | F42: =IFERROR(D42*E42,"") -> 1996.4725 | G42: =Campaign_data!F42 -> 2101.55
A43: =Campaign_data!A43 -> 42 | B43: =Campaign_data!D43 -> 6317.97 | C43: =Campaign_data!K43 -> 0.38404108 | D43: =B43 -> 6317.97 | E43: =C43 -> 0.38404108 | F43: =IFERROR(D43*E43,"") -> 2426.36 | G43: =Campaign_data!F43 -> 2426.36 | I43: Campaign with low roas | J43: =C42 -> 0.39585637 | K43: d42
A44: =Campaign_data!A44 -> 43 | B44: =Campaign_data!D44 -> 0 | C44: =Campaign_data!K44 | D44: =B44 -> 0 | E44: =C44 | F44: =IFERROR(D44*E44,"") | G44: =Campaign_data!F44 -> 21508.91 | I44: Campaign with high roas | J44: =C247 -> 0.36242882
A45: =Campaign_data!A45 -> 44 | B45: =Campaign_data!D45 -> 0 | C45: =Campaign_data!K45 | D45: =B45 -> 0 | E45: =C45 | F45: =IFERROR(D45*E45,"") | G45: =Campaign_data!F45 -> 31213.2
A46: =Campaign_data!A46 -> 45 | B46: =Campaign_data!D46 -> 0 | C46: =Campaign_data!K46 | D46: =B46 -> 0 | E46: =C46 | F46: =IFERROR(D46*E46,"") | G46: =Campaign_data!F46 -> 6604.33
A47: =Campaign_data!A47 -> 46 | B47: =Campaign_data!D47 -> 0 | C47: =Campaign_data!K47 | D47: =B47 -> 0 | E47: =C47 | F47: =IFERROR(D47*E47,"") | G47: =Campaign_data!F47 -> 14535.19
A48: =Campaign_data!A48 -> 47 | B48: =Campaign_data!D48 -> 10353.45 | C48: =Campaign_data!K48 -> 0.35885912 | D48: =B48 -> 10353.45 | E48: =C48 -> 0.35885912 | F48: =IFERROR(D48*E48,"") -> 3715.43 | G48: =Campaign_data!F48 -> 3715.43 | I48: Campaign with high roas | J48: =C199 -> 3.2351815 | K48: d199
A49: =Campaign_data!A49 -> 48 | B49: =Campaign_data!D49 -> 28098.99 | C49: =Campaign_data!K49 -> 0.57281276 | D49: =B49 -> 28098.99 | E49: =C49 -> 0.57281276 | F49: =IFERROR(D49*E49,"") -> 16095.46 | G49: =Campaign_data!F49 -> 16095.46
A50: =Campaign_data!A50 -> 49 | B50: =Campaign_data!D50 -> 15451.23 | C50: =Campaign_data!K50 -> 0.5117735 | D50: =B50 -> 15451.23 | E50: =C50 -> 0.5117735 | F50: =IFERROR(D50*E50,"") -> 7907.53 | G50: =Campaign_data!F50 -> 7907.53 | I50: proposed budget changed for both cells | J50: d42 and d199
A51: =Campaign_data!A51 -> 50 | B51: =Campaign_data!D51 -> 0 | C51: =Campaign_data!K51 | D51: =B51 -> 0 | E51: =C51 | F51: =IFERROR(D51*E51,"") | G51: =Campaign_data!F51 -> 408.34
A52: =Campaign_data!A52 -> 51 | B52: =Campaign_data!D52 -> 3496.2 | C52: =Campaign_data!K52 -> 0.22922602 | D52: =B52 -> 3496.2 | E52: =C52 -> 0.22922602 | F52: =IFERROR(D52*E52,"") -> 801.42 | G52: =Campaign_data!F52 -> 801.42
A53: =Campaign_data!A53 -> 52 | B53: =Campaign_data!D53 -> 28820.82 | C53: =Campaign_data!K53 -> 0.58470855 | D53: =B53 -> 28820.82 | E53: =C53 -> 0.58470855 | F53: =IFERROR(D53*E53,"") -> 16851.78 | G53: =Campaign_data!F53 -> 16851.78
A54: =Campaign_data!A54 -> 53 | B54: =Campaign_data!D54 -> 19060.92 | C54: =Campaign_data!K54 -> 0.63322809 | D54: =B54 -> 19060.92 | E54: =C54 -> 0.63322809 | F54: =IFERROR(D54*E54,"") -> 12069.91 | G54: =Campaign_data!F54 -> 12069.91
A55: =Campaign_data!A55 -> 54 | B55: =Campaign_data!D55 -> 0 | C55: =Campaign_data!K55 | D55: =B55 -> 0 | E55: =C55 | F55: =IFERROR(D55*E55,"") | G55: =Campaign_data!F55 -> 6661.04
A56: =Campaign_data!A56 -> 55 | B56: =Campaign_data!D56 -> 0 | C56: =Campaign_data!K56 | D56: =B56 -> 0 | E56: =C56 | F56: =IFERROR(D56*E56,"") | G56: =Campaign_data!F56 -> 3606.15
A57: =Campaign_data!A57 -> 56 | B57: =Campaign_data!D57 -> 0 | C57: =Campaign_data!K57 | D57: =B57 -> 0 | E57: =C57 | F57: =IFERROR(D57*E57,"") | G57: =Campaign_data!F57 -> 5755.97
A58: =Campaign_data!A58 -> 57 | B58: =Campaign_data!D58 -> 5848.57 | C58: =Campaign_data!K58 -> 0.77134411 | D58: =B58 -> 5848.57 | E58: =C58 -> 0.77134411 | F58: =IFERROR(D58*E58,"") -> 4511.26 | G58: =Campaign_data!F58 -> 4511.26
A59: =Campaign_data!A59 -> 58 | B59: =Campaign_data!D59 -> 38829.94 | C59: =Campaign_data!K59 -> 0.59037923 | D59: =B59 -> 38829.94 | E59: =C59 -> 0.59037923 | F59: =IFERROR(D59*E59,"") -> 22924.39 | G59: =Campaign_data!F59 -> 22924.39
A60: =Campaign_data!A60 -> 59 | B60: =Campaign_data!D60 -> 0 | C60: =Campaign_data!K60 | D60: =B60 -> 0 | E60: =C60 | F60: =IFERROR(D60*E60,"") | G60: =Campaign_data!F60 -> 293.05
...

Sheet Scenario_Summary
A1: Metric | B1: Historic Baseline | C1: Proposed Baseline | D1: Difference
A2: Total Spend | B2: =SUM(Campaign_data!D2:D601) -> 3240599.2 | C2: =Budget_Scenario!J3 -> 3240599.2 | D2: =ABS(C2-B2) -> 0
A3: Reported/Expected Conversion Value | B3: =SUM(Campaign_data!F2:F601) -> 2524740.6 | C3: =Budget_Scenario!J7 -> 1751987.8 | D3: =ABS(C3-B3) -> 772752.82
A4: ROAS | B4: =Budget_Scenario!J6 -> 0.77909684 | C4: =Budget_Scenario!J8 -> 0.54063699 | D4: =ABS(C4-B4) -> 0.23845986
